<?xml version="1.0"?>
<!-- created with Phobos 0.7 -->
  <robot name="dbw_mkz" xmlns:xacro="http://www.ros.org/wiki/xacro">
    <xacro:arg name="dae_file" default="$(find dbw_mkz_description)/meshes/mkz_13/body.dae"/>
    
    <link name="base_link"> </link>

    <link name="base_wheel">
      <inertial>
        <origin xyz="1.4225 0 0.25" rpy="0 0 0"/>
        <mass value="1500.0"/>
        <inertia ixx="1000.0" ixy="0" ixz="0" iyy="1000.0" iyz="0" izz="1000.0"/>
      </inertial>
      <visual name="chassis">
        <origin xyz="1.3641 0 -0.33" rpy="0 0 1.570796"/>
        <geometry>
          <mesh filename="file://$(arg dae_file)" scale="0.38 0.394 0.394"/>
        </geometry>
        <material name="black.001"/>
      </visual>
      <collision name="chassis_collision">
        <origin xyz="1.51 -0.03046 0.350609" rpy="1.570796 0 -3.141593"/>
        <geometry>
          <mesh filename="package://dbw_mkz_description/meshes/body_collision.stl" scale="0.001 0.001 0.001"/>
        </geometry>
      </collision>
    </link>

    <link name="steer_fl">
      <inertial>
        <origin xyz="-0.013054 -0.0295 0" rpy="0 0 0"/>
        <mass value="1.0"/>
        <inertia ixx="0.037227" ixy="0" ixz="0" iyy="0.04" iyz="0" izz="0.06"/>
      </inertial>
    </link>

    <link name="steer_fr">
      <inertial>
        <origin xyz="-0.01305 0.0275 0" rpy="0 0 0"/>
        <mass value="1.0"/>
        <inertia ixx="0.037227" ixy="0" ixz="0" iyy="0.04" iyz="0" izz="0.06"/>
      </inertial>
    </link>

    <link name="wheel_fl">
      <inertial>
        <origin xyz="0 0 0" rpy="0 -3.141593 0"/>
        <mass value="10.0"/>
        <inertia ixx="0.305583" ixy="0" ixz="0" iyy="0.305583" iyz="0" izz="0.5445"/>
      </inertial>
      <visual name="wheel_fl_visual">
        <origin xyz="0 0 0.0385" rpy="-1.570796 -1.570796 0"/>
        <geometry>
          <mesh filename="package://dbw_mkz_description/meshes/mkz_13/wheel.dae" scale="0.01 0.01 0.01"/>
        </geometry>
        <material name="carpaint_002"/>
      </visual>
      <collision name="wheel_fl_collision">
        <origin xyz="0 0 0" rpy="0 -3.141593 0"/>
        <geometry>
          <cylinder radius="0.33" length="0.2"/>
        </geometry>
      </collision>
    </link>

    <link name="wheel_fr">
      <inertial>
        <origin xyz="0 0 0" rpy="0 3.141593 0"/>
        <mass value="10.0"/>
        <inertia ixx="0.305583" ixy="0" ixz="0" iyy="0.305583" iyz="0" izz="0.5445"/>
      </inertial>
      <visual name="wheel_fr_visual">
        <origin xyz="0 0 -0.043777" rpy="-1.570796 1.570796 0"/>
        <geometry>
          <mesh filename="package://dbw_mkz_description/meshes/mkz_13/wheel.dae" scale="0.01 0.01 0.01"/>
        </geometry>
        <material name="carpaint_002.001"/>
      </visual>
      <collision name="wheel_fr_collision">
        <origin xyz="0 0 -0.0035" rpy="0 3.141593 0"/>
        <geometry>
          <cylinder radius="0.33" length="0.2"/>
        </geometry>
      </collision>
    </link>

    <link name="wheel_rl">
      <inertial>
        <origin xyz="0 0 0" rpy="0 3.141593 0"/>
        <mass value="10.0"/>
        <inertia ixx="0.305583" ixy="0" ixz="0" iyy="0.305583" iyz="0" izz="0.5445"/>
      </inertial>
      <visual name="wheel_rl_visual">
        <origin xyz="0 0 0.017382" rpy="-1.570796 -1.570796 0"/>
        <geometry>
          <mesh filename="package://dbw_mkz_description/meshes/mkz_13/wheel.dae" scale="0.01 0.01 0.01"/>
        </geometry>
        <material name="carpaint_002.003"/>
      </visual>
      <collision name="wheel_rl_collision">
        <origin xyz="0 0 -0.021118" rpy="0 3.141593 0"/>
        <geometry>
          <cylinder radius="0.33" length="0.2"/>
        </geometry>
      </collision>
    </link>

    <link name="wheel_rr">
      <inertial>
        <origin xyz="0 0 0" rpy="0 3.141593 0"/>
        <mass value="10.0"/>
        <inertia ixx="0.305583" ixy="0" ixz="0" iyy="0.305583" iyz="0" izz="0.5445"/>
      </inertial>
      <visual name="wheel_rr_visual">
        <origin xyz="0 0 -0.019214" rpy="-1.570796 1.570796 0"/>
        <geometry>
          <mesh filename="package://dbw_mkz_description/meshes/mkz_13/wheel.dae" scale="0.01 0.01 0.01"/>
        </geometry>
        <material name="carpaint_002.002"/>
      </visual>
      <collision name="wheel_rr_collision">
        <origin xyz="0 0 0.0205" rpy="0 3.141593 0"/>
        <geometry>
          <cylinder radius="0.33" length="0.2"/>
        </geometry>
      </collision>
    </link>

    <joint name="base_wheel_joint" type="fixed">
      <origin xyz="0 0 0.33" rpy="0 0 0"/>
      <parent link="base_link"/>
      <child link="base_wheel"/>
    </joint>

    <joint name="steer_fl_joint" type="fixed">
      <origin xyz="2.85 0.79121 0.0" rpy="0 0 0"/>
      <parent link="base_wheel"/>
      <child link="steer_fl"/>
      <axis xyz="0 0 1.0"/>
      <limit lower="-0.6" upper="0.6" effort="0" velocity="0"/>
    </joint>

    <joint name="steer_fr_joint" type="revolute">
      <origin xyz="2.85 -0.79121 0.0" rpy="0 0 0"/>
      <parent link="base_wheel"/>
      <child link="steer_fr"/>
      <axis xyz="0 0 1.0"/>
      <limit lower="-0.6" upper="0.6" effort="0" velocity="0"/>
    </joint>

    <joint name="wheel_fl_joint" type="continuous">
      <origin xyz="0 0 0" rpy="1.570796 0 -3.141593"/>
      <parent link="steer_fl"/>
      <child link="wheel_fl"/>
      <axis xyz="0 0 1.0"/>
      <limit effort="0" velocity="22.0"/>
    </joint>

    <joint name="wheel_fr_joint" type="continuous">
      <origin xyz="0 0 0" rpy="1.570796 0 -3.141593"/>
      <parent link="steer_fr"/>
      <child link="wheel_fr"/>
      <axis xyz="0 0 1.0"/>
      <limit effort="0" velocity="22.0"/>
    </joint>

    <joint name="wheel_rl_joint" type="fixed">
      <origin xyz="0 0.7874 0" rpy="1.570796 0 -3.141593"/>
      <parent link="base_wheel"/>
      <child link="wheel_rl"/>
      <axis xyz="0 0 1.0"/>
      <limit effort="5000.0" velocity="22.0"/>
    </joint>

    <joint name="wheel_rr_joint" type="continuous">
      <origin xyz="0 -0.7874 0" rpy="1.570796 0 -3.141593"/>
      <parent link="base_wheel"/>
      <child link="wheel_rr"/>
      <axis xyz="0 0 1.0"/>
      <limit effort="5000.0" velocity="22.0"/>
    </joint>
    
    
    <!-- MKZ Sensors /-->
    
    <link name="sensor_kit_base_link"> </link>
	<joint name="sensor_kit_base_link_joint" type="fixed">
	  <parent link="base_link" />
	  <child link="sensor_kit_base_link" />
	  <origin xyz="0.9652 0 2.15" rpy="-0.004159 -0.00262 0" />
	</joint>		
      
    <link name="os_sensor">
      <inertial>
         <mass value="0.33"/>
         <origin xyz="0 0 0.0365" rpy="0 0 0" />
         <inertia ixx="0.000241148" ixy="0" ixz="0"
          iyy="0.000241148" iyz="0" izz="0.000264"/>
      </inertial>
      <collision name="base_collision">
         <origin xyz="0 0 0.0365" rpy="0 0 0" />
         <geometry>
 	        <cylinder radius="0.04" length="0.073"/>
         </geometry>
      </collision>
      <visual name="base_visual">
         <origin xyz="0 0 0.0" rpy="0 0 1.5707" />
         <geometry>
	         <mesh filename="package://ouster_os1_64/meshes/os1_64.dae" /> 
           <!-- <cylinder length="0.073" radius="0.04" /> -->
         </geometry>
      </visual>
    </link>
    
	<joint name="os_sensor_joint" type="fixed">
	  <parent link="sensor_kit_base_link" />
	  <child link="os_sensor" />
	  <origin xyz="0.0 0 0" rpy="0 0 0" />
	</joint>
		
		
    <link name="os_imu"> </link>
	<joint name="os_imu_joint" type="fixed">
	  <parent link="sensor_kit_base_link" />
	  <child link="os_imu" />
	  <origin xyz="0 0 0" rpy="0 0 0" />
	</joint>

	<link name="velodyne_front"> </link>
	<joint name="velodyne_front_joint" type="fixed">
	  <parent link="sensor_kit_base_link" />
	  <child link="velodyne_front" />
	  <origin xyz="0.852345 0.00876912 -0.3" rpy="-0.0197 0.6143 -0.0273" />
	</joint>

	<link name="velodyne_right"> </link>
	<joint name="velodyne_right_joint" type="fixed">
	  <parent link="sensor_kit_base_link" />
	  <child link="velodyne_right" />
	  <origin xyz="-0.0606121 -0.437449 -0.550837" rpy="-0.01  0.71 -1.580" />
	</joint>

	<link name="velodyne_left"> </link>
	<joint name="velodyne_left_joint" type="fixed">
	  <parent link="sensor_kit_base_link" />
	  <child link="velodyne_left" />
	  <origin xyz="-0.068965 0.485312 -0.542697" rpy="-0.0158 0.2061 1.4732" />
	</joint>

	<link name="camera_optical"> </link>
	<joint name="camera_optical_joint" type="fixed">
	  <parent link="sensor_kit_base_link" />
	  <child link="camera_optical" />
	  <origin xyz="0.457241 -0.349859 -0.100585" rpy="2.71 -1.5031 -1.1236" />
	</joint>


	<!-- Color Information /-->
    <material name="black.001">
      <color rgba="0 0 0 1.0"/>
    </material>

    <material name="carpaint_002">
      <color rgba="0.941177 0.941177 0.941177 1.0"/>
    </material>

    <material name="carpaint_002.001">
      <color rgba="0.941177 0.941177 0.941177 1.0"/>
    </material>

    <material name="carpaint_002.002">
      <color rgba="0.941177 0.941177 0.941177 1.0"/>
    </material>

    <material name="carpaint_002.003">
      <color rgba="0.941177 0.941177 0.941177 1.0"/>
    </material>

  </robot>
